<?xml version ="1.0"?> <!--ประกาศ version-->
<robot name = "robot1_arm"> <!--ชื่อหุ่นยนต์-->

<!-- ส่วนประกอบของ link คือ name , visual , collision , inertial -->
<!-- ใน ros ส่วนมากจะใช้หน่วย กิโลกรัม กับ เมตร -->
<!-- base link-->

<link name = "base_link"/>


<!-- link1 -->
<link name = "link1">
    <visual>
    <!--รูปลักษณ์-->
        <geometry>
            <!-- ทรงกระบอก ยาว 0.1 เมตร รัศมี 0.1-->
            <cylinder length = "0.1" radius ="0.1"/>
        </geometry>
        <!-- เริ่มต้นที่จุด: 0 0 0 ,โรล พิช ยอ: 0 0 0-->
        <origin xyz = "0 0 0" rpy = "0 0 0"/>
    </visual>

    <collision>
    <!--กันชน-->
        <geometry>
            <!-- ทรงกระบอก ยาว 0.1 เมตร รัศมี 0.1-->
            <cylinder length = "0.1" radius ="0.1"/>
        </geometry>
        <!-- เริ่มต้นที่จุด: 0 0 0 ,โรล พิช ยอ: 0 0 0-->
        <origin xyz = "0 0 0" rpy = "0 0 0"/>
    </collision>


    <inertial>
    <!--มวลต่างๆที่เกี่ยวข้องกับ link ของเรา-->
        <!-- เริ่มต้นที่จุด: 0 0 0 ,โรล พิช ยอ: 0 0 0-->
        <origin xyz = "0 0 0" rpy = "0 0 0"/>
        <!--มวล 1 กิโลกรัม-->
        <mass value ="1"/>
        <!-- ค่าความเค้น หน่วยเป็น นิวตันเมตร หาได้จากการคำนวน-->
        <inertia ixx ="0.001" ixy ="0" ixz ="0" iyy="0.001" iyz="0" izz = "0.001"/>
    </inertial>
</link>

<!--joint1-->
<joint name ="joint1" type ="revolute">
    <parent link="base_link"/>
    <child link="link1"/>
    <!-- เริ่มต้นที่จุด: 0 0 0 ,โรล พิช ยอ: 0 0 0-->
    <origin xyz="0 0 0" rpy="0 0 0"/>
    <!-- ต้องการให้หมุนแกน z -->
    <axis xyz="0 0 1"/>
    <!--lower :ค่าน้อยสุดที่หมุนได้ , upper :ค่ามากสุดที่หมุนได้ ,effort : ค่าความเฉื่อย , velocity : ความเร็ว-->
    <limit lower="-3.1416" upper="3.1416" effort="100" velocity="1"/>
</joint>

<!-- link2 -->
<link name = "link2">
    <visual>
    <!--รูปลักษณ์-->
        <geometry>
            <!-- กว้าง * ยาว * สูง  10*10*10 ซม.-->
            <box size ="0.1 1 0.1"/>
        </geometry>
        <!-- เริ่มต้นที่จุด: 0 0 0 ,โรล พิช ยอ: 0 0 0-->
        <origin xyz = "0 0 0" rpy = "0 0 0"/>
    </visual>

    <collision>
    <!--กันชน-->
        <geometry>
            <!-- กว้าง * ยาว * สูง  10*10*10 ซม.-->
            <box size ="0.1 1 0.1"/>
        </geometry>
        <!-- เริ่มต้นที่จุด: 0 0 0 ,โรล พิช ยอ: 0 0 0-->
        <origin xyz = "0 0 0" rpy = "0 0 0"/>
    </collision>


    <inertial>
    <!--มวลต่างๆที่เกี่ยวข้องกับ link ของเรา-->
        <!-- เริ่มต้นที่จุด: 0 0 0 ,โรล พิช ยอ: 0 0 0-->
        <origin xyz = "0 0 0" rpy = "0 0 0"/>
        <!--มวล 1 กิโลกรัม-->
        <mass value ="1"/>
        <!-- ค่าความเค้น หน่วยเป็น นิวตันเมตร หาได้จากการคำนวน-->
        <inertia ixx ="0.001" ixy ="0" ixz ="0" iyy="0.001" iyz="0" izz = "0.001"/>
    </inertial>
</link>

<!--joint2-->
<joint name ="joint2" type ="prismatic">
    <parent link="link1"/>
    <child link="link2"/>
    <!-- เริ่มต้นที่จุด: 0 0 0.1 (ยกขึนมา 10 ซม.) ,โรล พิช ยอ: 0 0 0-->
    <origin xyz="0 0 0.1" rpy="0 0 0"/>
    <!-- ต้องการให้หมุนแกน Y -->
    <axis xyz="0 1 0"/>
    <!--lower :ค่าน้อยสุดที่หมุนได้ , upper :ค่ามากสุดที่หมุนได้ ,effort : ค่าความเฉื่อย , velocity : ความเร็ว-->
    <limit lower="-0.5" upper="0.5" effort="100" velocity="1"/>
</joint>



<!-- link3 -->
<link name = "link3">
    <visual>
    <!--รูปลักษณ์-->
        <geometry>
            <!-- กว้าง * ยาว * สูง  10*10*10 ซม.-->
            <box size ="1 0.1 0.1"/>
        </geometry>
        <!-- เริ่มต้นที่จุด: 0 0 0 ,โรล พิช ยอ: 0 0 0-->
        <origin xyz = "0 0 0" rpy = "0 0 0"/>
    </visual>

    <collision>
    <!--กันชน-->
        <geometry>
            <!-- กว้าง * ยาว * สูง  10*10*10 ซม.-->
            <box size ="1 0.1 0.1"/>
        </geometry>
        <!-- เริ่มต้นที่จุด: 0 0 0 ,โรล พิช ยอ: 0 0 0-->
        <origin xyz = "0 0 0" rpy = "0 0 0"/>
    </collision>


    <inertial>
    <!--มวลต่างๆที่เกี่ยวข้องกับ link ของเรา-->
        <!-- เริ่มต้นที่จุด: 0 0 0 ,โรล พิช ยอ: 0 0 0-->
        <origin xyz = "0 0 0" rpy = "0 0 0"/>
        <!--มวล 1 กิโลกรัม-->
        <mass value ="1"/>
        <!-- ค่าความเค้น หน่วยเป็น นิวตันเมตร หาได้จากการคำนวน-->
        <inertia ixx ="0.001" ixy ="0" ixz ="0" iyy="0.001" iyz="0" izz = "0.001"/>
    </inertial>
</link>

<!--joint3-->
<joint name ="joint3" type ="prismatic">
    <parent link="link2"/>
    <child link="link3"/>
    <!-- เริ่มต้นที่จุด: 0 0 0.1 (ยกขึนมา 10 ซม.) ,โรล พิช ยอ: 0 0 0-->
    <origin xyz="0 0 0.1" rpy="0 0 0"/>
    <!-- ต้องการให้หมุนแกน Y -->
    <axis xyz="1 0 0"/>
    <!--lower :ค่าน้อยสุดที่หมุนได้ , upper :ค่ามากสุดที่หมุนได้ ,effort : ค่าความเฉื่อย , velocity : ความเร็ว-->
    <limit lower="-0.4" upper="0.4" effort="100" velocity="1"/>
</joint>


<!-- link4 -->
<link name = "link4">
    <visual>
    <!--รูปลักษณ์-->
        <geometry>
            <!-- ทรงกระบอก ยาว 0.1 เมตร รัศมี 0.1-->
            <cylinder length = "0.1" radius ="0.1"/>
        </geometry>
        <!-- เริ่มต้นที่จุด: 0 0 0 ,โรล พิช ยอ: 0 0 0-->
        <origin xyz = "0 0 0" rpy = "0 0 0"/>
    </visual>

    <collision>
    <!--กันชน-->
        <geometry>
            <!-- ทรงกระบอก ยาว 0.1 เมตร รัศมี 0.1-->
            <cylinder length = "0.1" radius ="0.1"/>
        </geometry>
        <!-- เริ่มต้นที่จุด: 0 0 0 ,โรล พิช ยอ: 0 0 0-->
        <origin xyz = "0 0 0" rpy = "0 0 0"/>
    </collision>


    <inertial>
    <!--มวลต่างๆที่เกี่ยวข้องกับ link ของเรา-->
        <!-- เริ่มต้นที่จุด: 0 0 0 ,โรล พิช ยอ: 0 0 0-->
        <origin xyz = "0 0 0" rpy = "0 0 0"/>
        <!--มวล 1 กิโลกรัม-->
        <mass value ="1"/>
        <!-- ค่าความเค้น หน่วยเป็น นิวตันเมตร หาได้จากการคำนวน-->
        <inertia ixx ="0.001" ixy ="0" ixz ="0" iyy="0.001" iyz="0" izz = "0.001"/>
    </inertial>
</link>

<!--joint4-->
<joint name ="joint4" type ="revolute">
    <parent link="link3"/>
    <child link="link4"/>
    <!-- เริ่มต้นที่จุด: 0 0 0 ,โรล พิช ยอ: 0 0 0-->
    <origin xyz="0.4 0 0.1" rpy="0 0 0"/>
    <!-- ต้องการให้หมุนแกน z -->
    <axis xyz="0 0 1"/>
    <!--lower :ค่าน้อยสุดที่หมุนได้ , upper :ค่ามากสุดที่หมุนได้ ,effort : ค่าความเฉื่อย , velocity : ความเร็ว-->
    <limit lower="-3.1416" upper="3.1416" effort="100" velocity="1"/>
</joint>
</robot>